Workbook

Sheet Đọc trước
A1: FlowWise: đặc tả sản phẩm cho team
A2: Sản phẩm trong 3 câu
A3: 1. SME tự upload file số liệu (sao kê, phải thu, phải trả, chi phí định kỳ); hệ thống kiểm tra, chuẩn hóa thành các khoản tiền có ngày.
A4: 2. Engine tính xác định số dư 13 tuần cho từng đồng tiền (VND, CNY, USD), cảnh báo tuần dưới mức an toàn và so sánh phương án xử lý.
A5: 3. AI là trợ lý hỏi đáp: gọi engine rồi giải thích bằng tiếng Việt; AI không tự tạo ra con số.
A7: Luồng tổng thể
A8: Upload file → Ánh xạ cột → Kiểm tra dữ liệu → Tạo cash_event → Dự báo 13 tuần (mỗi đồng tiền) → Cảnh báo + nguyên nhân → Kịch bản + so sánh → Phê duyệt + báo cáo
A10: Tổng hợp tiến độ (tự cập nhật)
A11: Số tính năng P0 | B11: =COUNTIF('Phạm vi MVP'!D5:D28,"P0") -> 11
A12: P0 đã xong | B12: =COUNTIFS('Phạm vi MVP'!D5:D28,"P0",'Phạm vi MVP'!H5:H28,"Xong") -> 0
A13: Số tính năng P1 | B13: =COUNTIF('Phạm vi MVP'!D5:D28,"P1") -> 8
A14: Số quy tắc dữ liệu | B14: =COUNTA('Quy tắc dữ liệu'!A5:A29) -> 25
A15: Số test case | B15: =COUNTA('Test case'!A5:A30) -> 26
A16: Test đạt | B16: =COUNTIF('Test case'!H5:H30,"Đạt") -> 0
A17: Quyết định chưa chốt | B17: =COUNTIF('Quyết định mở'!I2:I14,"Chưa chốt") -> 13
A19: Danh mục sheet
A20: Sheet | B20: Cho ai | C20: Nội dung
A21: Phạm vi MVP | B21: Cả team | C21: Danh sách tính năng, ưu tiên và tiêu chí xong
A22: Đầu vào | B22: Dev | C22: Trường nào của từng file, bắt buộc hay không, kiểm tra thế nào
A23: Ánh xạ cột | B23: Dev | C23: Cách nhận diện cột, định dạng ngày/số, UX ánh xạ
A24: Quy tắc dữ liệu | B24: Dev | C24: 25 quy tắc kiểm tra và thông báo cho người dùng
A25: Mô hình dữ liệu | B25: Dev | C25: Các bảng/đối tượng và trường
A26: Logic dự báo | B26: Dev | C26: Các bước tính và nguyên tắc bất biến
A27: Tham số | B27: Business + Dev | C27: Giá trị mặc định của mọi tham số
A28: Ví dụ tính tay | B28: Dev | C28: Bản Excel của engine để đối chiếu số
A29: Kịch bản | B29: Dev | C29: Ba kịch bản mô phỏng và chỉ số so sánh
A30: Đầu ra | B30: Dev + UI | C30: Màn hình và nội dung báo cáo
A31: AI | B31: Dev | C31: Tool, câu hỏi nghiệm thu, guardrail
... A37: Thuật ngữ & UI copy | B37: Cả team | C37: Cách gọi chung và cách viết trên giao diện
A39: Quy ước
A40: Ô nền vàng chữ xanh dương: ô cần Business/Dev điền hoặc chốt.
A41: Chữ xanh lá: giá trị lấy từ sheet khác. Chữ đen: nội dung cố định hoặc công thức.
A42: Số liệu ví dụ là dữ liệu giả lập, không phải số thật của shop nào.
A43: Các con số đề xuất (giới hạn file, tham số) cần dev và Business xác nhận trước khi dùng.

Sheet Phạm vi MVP
A1: Phạm vi MVP: tính năng, ưu tiên, tiêu chí nghiệm thu
A2: P0 = bắt buộc cho bản nộp; P1 = làm nếu kịp; P2 = để sau; KHÔNG = chủ động không làm. Cột vàng do team điền.
A4: ID | B4: Tính năng | C4: Mô tả | D4: Ưu tiên | E4: Phụ thuộc | F4: Tiêu chí nghiệm thu (dev biết khi nào xong) | G4: Owner | H4: Trạng thái | I4: Ghi chú
A5: F01 | B5: Upload file | C5: Tải lên 1 hoặc nhiều file CSV/XLSX (sao kê, phải thu, phải trả, chi phí định kỳ). | D5: P0 | E5: - | F5: Tải được file ≤ giới hạn ở sheet Phi chức năng; hiện danh sách file đã tải; xóa được file. | H5: Chưa làm
A6: F02 | B6: Ánh xạ cột | C6: Hệ thống gợi ý cột nào là ngày/số tiền/tiền tệ; người dùng xác nhận hoặc sửa. Lưu lại ánh xạ cho lần sau. | D6: P0 | E6: F01 | F6: File có tên cột lạ vẫn nhập được sau khi người dùng chọn tay; hỗ trợ cả 1 cột số tiền có dấu và 2 cột Ghi nợ/Ghi có. | H6: Chưa làm
A7: F03 | B7: Kiểm tra dữ liệu | C7: Áp toàn bộ quy tắc ở sheet Quy tắc dữ liệu; hiện báo cáo lỗi theo mức Chặn/Cảnh báo/Thông tin kèm số dòng. | D7: P0 | E7: F02 | F7: Mỗi quy tắc V01–V25 có test; lỗi hiển thị số dòng và tên file; không tự xóa dữ liệu nghi trùng. | H7: Chưa làm
A8: F04 | B8: Chuẩn hóa thành cash event | C8: Mọi dòng hợp lệ trở thành cash_event (ngày, số tiền có dấu, tiền tệ, loại, nguồn). | D8: P0 | E8: F03 | F8: Mỗi event truy được về file + dòng gốc; tổng event khớp tổng dòng hợp lệ. | H8: Chưa làm
A9: F05 | B9: Thiết lập đầu kỳ | C9: Form nhập ngày chốt, số dư đầu kỳ và ngưỡng an toàn cho từng đồng tiền. | D9: P0 | E9: - | F9: Không cho dự báo khi thiếu ngày chốt hoặc số dư; ngưỡng mặc định gợi ý theo Tham số P05. | H9: Chưa làm
A10: F06 | B10: Dự báo 13 tuần: VND | C10: Tính số dư cuối mỗi tuần cho VND theo sheet Logic dự báo. | D10: P0 | E10: F04, F05 | F10: Kết quả khớp sheet Ví dụ tính tay (TC01–TC06). | H10: Chưa làm
A11: F07 | B11: Dự báo 13 tuần: CNY và USD | C11: Chạy cùng engine cho CNY, USD, tách biệt hoàn toàn với VND. | D11: P1 | E11: F06 | F11: TC09 đạt: đổi dữ liệu VND không làm đổi CNY/USD. | H11: Chưa làm
A12: F08 | B12: Cảnh báo hai mức | C12: SHORTFALL (số dư < 0) và BELOW_BUFFER (số dư < ngưỡng); nêu tuần đầu tiên, khoảng thiếu, top 3 khoản gây ảnh hưởng. | D12: P0 | E12: F06 | F12: TC02–TC04, TC25 đạt; mỗi driver có link tới file/dòng. | H12: Chưa làm
A13: F09 | B13: Kịch bản: dời khoản phải trả | C13: Chọn bill đủ điều kiện, dời N ngày, chạy lại forecast. | D13: P0 | E13: F06 | F13: TC07, TC08 đạt. | H13: Chưa làm
A14: F10 | B14: Kịch bản: thu sớm | C14: Chọn hóa đơn phải thu, % ưu đãi, ngày thu mới. | D14: P1 | E14: F06 | F14: Số tiền thu giảm đúng theo % ưu đãi; chi phí ưu đãi hiển thị. | H14: Chưa làm
A15: F11 | B15: Kịch bản: khoản vay giả lập | C15: Giải ngân + lịch trả gốc/lãi cùng đồng tiền. | D15: P1 | E15: F06 | F15: Lịch trả khớp công thức ở sheet Kịch bản; nhãn 'giả định'. | H15: Chưa làm
A16: F12 | B16: So sánh baseline và kịch bản | C16: Bảng so sánh số dư thấp nhất, tuần vi phạm đầu tiên, khoảng thiếu, chi phí. | D16: P0 | E16: F09 | F16: Kịch bản rỗng ra đúng baseline (TC07). | H16: Chưa làm
... A28: F24 | B28: Tự động chuyển tiền/vay thật | C28: Thực hiện giao dịch. | D28: KHÔNG | E28: - | F28: Chỉ mô phỏng và lập kế hoạch. | H28: Chưa làm

Sheet Đầu vào
A1: Đặc tả file đầu vào
A2: SME tự upload file. Mỗi dòng là một trường: có bắt buộc không, kiểu gì, kiểm tra thế nào, sai thì xử lý ra sao.
A4: Loại file | B4: Trường | C4: Bắt buộc | D4: Kiểu | E4: Định dạng / ý nghĩa | F4: Ví dụ (minh họa) | G4: Quy tắc kiểm tra | H4: Quy tắc dữ liệu liên quan | I4: Ghi chú cho dev
A5: Sao kê ngân hàng | B5: date | C5: Có | D5: Ngày | E5: YYYY-MM-DD hoặc DD/MM/YYYY | F5: 2026-10-06 | G5: Parse được; không sau ngày chốt | H5: V04, V05, V19 | I5: Ngày giao dịch thực tế
A6: Sao kê ngân hàng | B6: amount | C6: Có điều kiện | D6: Số | E6: Có dấu: vào +, ra − | F6: -12500000 | G6: Là số; ≠ 0 | H6: V06, V07, V08 | I6: Có thể thay bằng 2 cột debit/credit
A7: Sao kê ngân hàng | B7: debit (Ghi nợ) | C7: Có điều kiện | D7: Số ≥ 0 | E7: Tiền ra | F7: 12500000 | G7: Chỉ dùng khi không có amount | H7: V06 | I7: Quy đổi: amount = −debit
A8: Sao kê ngân hàng | B8: credit (Ghi có) | C8: Có điều kiện | D8: Số ≥ 0 | E8: Tiền vào | F8: 45000000 | G8: Chỉ dùng khi không có amount | H8: V06 | I8: Quy đổi: amount = +credit
A9: Sao kê ngân hàng | B9: currency | C9: Không | D9: Mã ISO | E9: VND / CNY / USD | F9: VND | G9: Thuộc danh sách hỗ trợ | H9: V09, V10 | I9: Thiếu thì lấy mặc định của tài khoản
A10: Sao kê ngân hàng | B10: description | C10: Không | D10: Văn bản | E10: Tự do | F10: CK tien hang NCC A | G10: Không bắt buộc | H10: - | I10: Hiển thị khi giải thích nguyên nhân
A11: Sao kê ngân hàng | B11: balance | C11: Không | D11: Số | E11: Số dư sau giao dịch | F11: 280000000 | G11: Là số | H11: V18 | I11: Chỉ để đối chiếu, không dùng làm số dư đầu kỳ
A12: Sao kê ngân hàng | B12: reference_id | C12: Không | D12: Văn bản | E12: Mã tham chiếu | F12: FT26279001 | G12: Duy nhất nếu có | H12: V11 | I12: Chống tính trùng
A13: Phải thu | B13: invoice_id | C13: Có | D13: Văn bản | E13: Tự do | F13: INV-2026-014 | G13: Duy nhất | H13: V11 | I13: Khóa của khoản phải thu
A14: Phải thu | B14: customer_alias | C14: Không | D14: Văn bản | E14: Tên/ alias khách | F14: Khach B2B-03 | G14: - | H14: - | I14: Nên là alias, không dùng tên thật khi demo
A15: Phải thu | B15: issue_date | C15: Không | D15: Ngày | E15: như date | F15: 2026-09-20 | G15: Parse được | H15: V04 | I15: -
... A43: Đối soát sàn (tùy chọn) | B43: expected_payout_date | C43: Có (khi dùng) | D43: Ngày | E43: Ngày tiền về dự kiến | F43: 2026-10-15 | G43: Parse được | H43: V04 | I43: Ngày của event payout
A44: Đối soát sàn (tùy chọn) | B44: actual_payout_date | C44: Không | D44: Ngày | E44: Ngày tiền thật sự về | G44: - | H44: - | I44: Dùng để ước lượng độ trễ (F21)
A45: Khoản vay (tùy chọn) | B45: loan_id / balance / annual_rate / payment_amount / next_due_date / currency | C45: Không | D45: Hỗn hợp | E45: Khoản vay hiện có | F45: L01 / 500000000 / 0.11 / 15000000 / 2026-10-30 / VND | G45: Số hợp lệ | H45: V06 | I45: Sinh event trả nợ định kỳ
A47: Ví dụ dữ liệu là số minh họa. Mức độ 'Bắt buộc' là đề xuất, dev đối chiếu với F03 và Quy tắc dữ liệu trước khi code.

Sheet Ánh xạ cột
A1: Ánh xạ cột và định dạng file thực tế
A2: A. Từ khóa gợi ý nhận diện cột (đề xuất, cần kiểm chứng với file thật của seller)
A3: Trường chuẩn | B3: Từ khóa tên cột thường gặp | C3: Ghi chú
A4: date | B4: ngày, ngày giao dịch, ngày gd, ngày hạch toán, date, transaction date, posting date | C4: So khớp không phân biệt hoa thường, bỏ dấu
A5: amount | B5: số tiền, giá trị, amount, value | C5: Cột có dấu hoặc không dấu
A6: debit | B6: ghi nợ, số tiền ghi nợ, tiền ra, rút, debit, withdrawal | C6: Tiền ra
A7: credit | B7: ghi có, số tiền ghi có, tiền vào, nộp, credit, deposit | C7: Tiền vào
A8: description | B8: nội dung, diễn giải, mô tả, nội dung giao dịch, description, memo, narrative | C8: -
A9: balance | B9: số dư, số dư cuối, balance, running balance | C9: -
A10: currency | B10: tiền tệ, loại tiền, đơn vị tiền, currency, ccy | C10: -
A11: reference_id | B11: mã giao dịch, số tham chiếu, mã tham chiếu, reference, ref no | C11: -
A12: due_date | B12: hạn thanh toán, ngày đến hạn, hạn trả, due date | C12: Phải thu / phải trả
A13: invoice_id / bill_id | B13: số hóa đơn, mã hóa đơn, số chứng từ, invoice no, bill no | C13: -
A15: B. Định dạng cần hỗ trợ khi đọc
A16: Chủ đề | B16: Cần hỗ trợ | C16: Cách xử lý
A17: Ngày | B17: DD/MM/YYYY, YYYY-MM-DD, DD-MM-YYYY, ngày dạng số của Excel | C17: Nếu cột có giá trị mơ hồ như 03/04/2026 thì hỏi người dùng chọn DD/MM hay MM/DD cho cả cột (V05). Mặc định DD/MM/YYYY.
A18: Số tiền | B18: 1.234.567,89 (kiểu VN) và 1,234,567.89 (kiểu Mỹ); số âm bằng dấu − hoặc ngoặc (1.000); có hậu tố đ/VND | C18: Tự đoán dấu phân cách từ cả cột; mơ hồ thì hỏi người dùng (V08).
A19: Mã hóa file | B19: UTF-8, UTF-8 có BOM; CSV phân cách bằng dấu phẩy hoặc chấm phẩy | C19: Đọc đúng tiếng Việt có dấu.
A20: Excel | B20: Nhiều sheet; dòng tiêu đề không nằm ở dòng 1; có dòng tổng cuối; ô gộp | C20: Cho chọn sheet và dòng tiêu đề (V02); bỏ dòng tổng.
A21: Kích thước | B21: Theo giới hạn ở sheet Phi chức năng | C21: Quá lớn thì chặn và gợi ý chia nhỏ (V22).
A23: C. Luồng trải nghiệm ánh xạ (UX)
A24: Bước | B24: Người dùng / hệ thống làm gì | C24: Ghi chú
A25: 1 | B25: Người dùng chọn loại file (sao kê / phải thu / phải trả / chi phí định kỳ) | C25: Quyết định danh sách trường chuẩn cần ánh xạ
A26: 2 | B26: Hệ thống đọc 20 dòng đầu, đoán dòng tiêu đề và gợi ý ánh xạ cột | C26: Dùng từ khóa ở mục A
A27: 3 | B27: Hiển thị bảng: cột trong file → trường chuẩn, kèm 3 dòng xem trước; người dùng sửa | C27: Trường bắt buộc chưa ánh xạ thì không cho tiếp tục (V03)
A28: 4 | B28: Chọn định dạng ngày và số nếu hệ thống chưa chắc | C28: V05, V08
A29: 5 | B29: Chạy kiểm tra, hiện báo cáo lỗi theo mức độ | C29: Xem sheet Quy tắc dữ liệu
A30: 6 | B30: Người dùng xác nhận; hệ thống lưu ánh xạ để dùng lại với file cùng cấu trúc | C30: Giảm thao tác cho lần sau

Sheet Quy tắc dữ liệu
A1: Quy tắc kiểm tra dữ liệu
A2: Mức độ: CHẶN = không cho tiếp tục; CẢNH BÁO = vẫn chạy nhưng báo rõ; THÔNG TIN = ghi nhận. Nguyên tắc: không tự xóa, không tự đoán.
A4: ID | B4: Quy tắc | C4: Mức độ | D4: Hệ thống làm gì | E4: Thông báo cho người dùng (tiếng Việt) | F4: Test liên quan
A5: V01 | B5: File không đọc được hoặc sai định dạng | C5: CHẶN | D5: Dừng, không lưu | E5: Không đọc được file này. Hãy dùng CSV hoặc XLSX. | F5: TC18
A6: V02 | B6: Không tìm thấy dòng tiêu đề | C6: CẢNH BÁO | D6: Cho người dùng chọn dòng tiêu đề | E6: Chưa nhận ra dòng tiêu đề. Bạn chọn dòng nào là tiêu đề? | F6: -
A7: V03 | B7: Trường bắt buộc chưa được ánh xạ | C7: CHẶN | D7: Không cho sang bước sau | E7: Cần chọn cột cho: {tên trường}. | F7: -
A8: V04 | B8: Ngày không đọc được | C8: CẢNH BÁO | D8: Loại dòng khỏi tính toán, liệt kê số dòng | E8: {n} dòng có ngày không hợp lệ nên chưa được tính. | F8: TC18
A9: V05 | B9: Ngày mơ hồ (DD/MM hay MM/DD) | C9: CẢNH BÁO | D9: Hỏi người dùng, áp cho cả cột | E9: Cột ngày có thể hiểu theo 2 cách. Bạn chọn định dạng đúng. | F9: TC12
A10: V06 | B10: Số tiền không đọc được | C10: CẢNH BÁO | D10: Loại dòng, liệt kê | E10: {n} dòng có số tiền không hợp lệ nên chưa được tính. | F10: -
A11: V07 | B11: Số tiền bằng 0 | C11: THÔNG TIN | D11: Bỏ qua dòng | E11: {n} dòng có số tiền 0 đã được bỏ qua. | F11: -
A12: V08 | B12: Dấu phân cách số mơ hồ | C12: CẢNH BÁO | D12: Hỏi người dùng xác nhận kiểu số | E12: Số tiền có thể viết theo 2 kiểu. Bạn chọn kiểu đúng. | F12: TC13
A13: V09 | B13: Thiếu tiền tệ | C13: CẢNH BÁO | D13: Dùng tiền tệ mặc định của tài khoản; nếu file nhiều tiền tệ không rõ thì CHẶN cột | E13: Chưa có cột tiền tệ nên coi là {mặc định}. | F13: -
A14: V10 | B14: Mã tiền tệ ngoài VND/CNY/USD | C14: CẢNH BÁO | D14: Không đưa vào forecast (MVP) | E14: Tiền tệ {x} chưa được hỗ trợ nên các dòng này chưa tính. | F14: -
A15: V11 | B15: Trùng mã (invoice_id, bill_id, settlement_id, reference_id) | C15: CẢNH BÁO | D15: Gắn cờ nghi trùng, KHÔNG tự xóa, hỏi người dùng giữ dòng nào | E15: Có {n} mã bị lặp. Bạn xem và chọn giữ dòng nào. | F15: TC11
... A29: V25 | B29: Hai file có khoảng ngày chồng lấn | C29: CẢNH BÁO | D29: Nhắc kiểm tra tải trùng | E29: Hai file có ngày trùng nhau. Có thể bị tính hai lần. | F29: TC11

Sheet Mô hình dữ liệu
A1: Mô hình dữ liệu (các bảng/đối tượng cần có)
A2: Mọi thứ xoay quanh cash_event. Tên trường là đề xuất để cả team dùng thống nhất.
A4: Đối tượng | B4: Trường | C4: Kiểu | D4: Bắt buộc | E4: Mô tả | F4: Ví dụ
A5: cash_event | B5: event_id | C5: Văn bản | D5: Có | E5: Mã duy nhất của khoản tiền | F5: E05
A6: cash_event | B6: date | C6: Ngày | D6: Có | E6: Ngày tiền vào/ra (dự kiến hoặc thực tế) | F6: 2026-10-22
A7: cash_event | B7: amount | C7: Số | D7: Có | E7: Có dấu: vào +, ra − | F7: -130000000
A8: cash_event | B8: currency | C8: Mã ISO | D8: Có | E8: VND / CNY / USD | F8: VND
A9: cash_event | B9: type | C9: Liệt kê | D9: Có | E9: bank / receivable / payable / recurring / settlement / hold_release / loan | F9: payable
A10: cash_event | B10: status | C10: Liệt kê | D10: Có | E10: actual (đã xảy ra) hoặc expected (dự kiến) | F10: expected
A11: cash_event | B11: description | C11: Văn bản | D11: Không | E11: Mô tả hiển thị cho người dùng | F11: Thanh toán NCC
A12: cash_event | B12: source_file / source_row | C12: Văn bản / Số | D12: Có | E12: Truy vết về file và dòng gốc | F12: bill.csv / 12
A13: cash_event | B13: flexible | C13: Boolean | D13: Không | E13: Cho phép dời ngày trong kịch bản | F13: true
A14: cash_event | B14: assumption_note | C14: Văn bản | D14: Không | E14: Giải thích nếu ngày/số tiền là giả định | F14: Trễ 3 ngày theo giả định
A15: source_file | B15: file_id / filename / uploaded_at / row_count / mapping_json | C15: Hỗn hợp | D15: Có | E15: Thông tin file và ánh xạ cột đã dùng | F15: -
... A22: approval | B22: run_id / scenario_id / approved_by / approved_at / assumptions_snapshot | C22: Hỗn hợp | D22: Có | E22: Quyết định phê duyệt | F22: -

Sheet Logic dự báo
A1: Logic dự báo: từ file đến số dư 13 tuần
A2: Engine tính bằng phép cộng trừ xác định. AI không tự tính. Sheet Ví dụ tính tay là bản Excel của chính logic này để dev đối chiếu.
A4: A. Ba tầng 'dự báo' (nói rõ để dev không gộp lại thành 'AI predict')
A5: Tầng | B5: Tên | C5: Ví dụ | D5: Cách làm | E5: Ưu tiên
A6: Tầng 1 | B6: Chắc chắn / đã biết ngày | C6: Hóa đơn phải thu/trả, lương, tiền thuê, trả nợ, payout đã có lịch | D6: Phép tính xác định, không học từ dữ liệu | E6: P0
A7: Tầng 2 | B7: Ước lượng thống kê | C7: Doanh thu tuần tới ≈ trung bình 4 tuần gần nhất; độ trễ thu trung bình; % hoàn/huỷ | D7: Thống kê đơn giản trên lịch sử, hiển thị nhãn 'ước lượng', chỉ bật khi đủ dữ liệu (V24) | E7: P1
A8: Tầng 3 | B8: AI (LLM) | C8: Hiểu câu hỏi, gọi tool, giải thích kết quả bằng tiếng Việt | D8: Không sinh ra số mới; chỉ đọc output của engine | E8: P0
A10: B. Các bước xử lý
A11: Bước | B11: Tên | C11: Đầu vào | D11: Xử lý | E11: Đầu ra | F11: Quy tắc/Test liên quan
A12: S01 | B12: Nhận file | C12: File upload | D12: Đọc CSV/XLSX, giữ source_file và source_row cho từng dòng | E12: Bảng dòng thô | F12: V01, V22, V23
A13: S02 | B13: Ánh xạ cột | C13: Dòng thô + ánh xạ | D13: Đổi tên cột theo ánh xạ người dùng xác nhận; quy đổi debit/credit thành amount có dấu | E13: Bảng đã chuẩn hóa tên cột | F13: V02, V03
A14: S03 | B14: Kiểm tra | C14: Bảng chuẩn hóa | D14: Áp V04–V25; dòng không hợp lệ không đi tiếp | E14: Dòng hợp lệ + danh sách data_issue | F14: V04–V19
A15: S04 | B15: Tạo cash_event | C15: Dòng hợp lệ | D15: Sao kê → actual (chỉ làm lịch sử). Phải thu → expected, date = due_date + độ trễ. Phải trả → expected, date = due_date. Chi phí định kỳ → sinh theo lịch trong 13 tuần. Đối soát sàn → event payout (+ event hold_release nếu có hold). Khoản vay hiện có → event trả nợ. | E15: Danh sách cash_event | F15: V14, V15
A16: S05 | B16: Tách theo tiền tệ | C16: cash_event | D16: Chia thành nhóm VND, CNY, USD; event khác tiền tệ tài khoản vào hàng đợi thủ công; KHÔNG quy đổi, KHÔNG cộng chéo | E16: 3 danh sách độc lập | F16: V20
A17: S06 | B17: Xác định tuần | C17: as_of_date | D17: Tuần n bắt đầu = as_of + 7×(n−1), kết thúc = bắt đầu + 6 (n = 1..13). Tuần 1 bắt đầu đúng ngày chốt | E17: 13 khoảng ngày | F17: D04
A18: S07 | B18: Gom theo tuần | C18: cash_event, 13 tuần | D18: inflow[w] = tổng amount > 0 có date trong tuần w; outflow[w] = tổng amount < 0 (số âm) | E18: inflow, outflow mỗi tuần
A19: S08 | B19: Chuỗi số dư | C19: opening_cash, inflow, outflow | D19: opening[1] = opening_cash; closing[w] = opening[w] + inflow[w] + outflow[w]; opening[w+1] = closing[w] | E19: opening, closing mỗi tuần | F19: TC05, TC06
A20: S09 | B20: Cảnh báo | C20: closing, buffer | D20: closing < 0 → SHORTFALL; closing < buffer → BELOW_BUFFER (so sánh nhỏ hơn hẳn, bằng ngưỡng thì không cảnh báo); gap = max(0, buffer − closing); drivers = 3 event có |amount| lớn nhất trong tuần đó | E20: alert + drivers | F20: TC02–TC04, TC25
A21: S10 | B21: Ước lượng thống kê (P1) | C21: Lịch sử bank/settlement | D21: Trung bình 4 tuần gần nhất cho thu từ bán hàng; độ trễ thu trung bình; chỉ khi đủ dữ liệu | E21: Event expected có nhãn 'ước lượng' | F21: V24
A22: S11 | B22: Kịch bản | C22: Event + tham số kịch bản | D22: Sao chép danh sách event, biến đổi theo loại kịch bản (sheet Kịch bản), chạy lại S06–S09 | E22: Run kịch bản | F22: TC07, TC08
A23: S12 | B23: So sánh và lưu | C23: Các run | D23: Lưu run: data_hash, formula_version, giả định; so sánh baseline với kịch bản | E23: Bảng so sánh | F23: -
A25: C. Nguyên tắc bất biến (dev nên viết test cho từng điều này)
A26: ID | B26: Nguyên tắc | C26: Test
A27: N1 | B27: Mọi khoản tiền đi qua cash_event; không có đường tính số nào khác | C27: -
A28: N2 | B28: closing[w] = opening[w+1] với mọi w | C28: TC05
A29: N3 | B29: Kịch bản rỗng cho đúng baseline | C29: TC07
A30: N4 | B30: Đổi dữ liệu của một đồng tiền không làm đổi kết quả đồng tiền khác | C30: TC09
A31: N5 | B31: Tổng inflow + outflow 13 tuần = closing[13] − opening_cash | C31: TC06
A32: N6 | B32: Không cộng số khác tiền tệ ở bất kỳ bước nào | C32: TC10
A33: N7 | B33: Cùng input và cùng phiên bản công thức thì cùng output | C33: -

Sheet Tham số
A1: Tham số và giả định của hệ thống
A2: Cột vàng là giá trị đề xuất, team chốt rồi dev cấu hình. Mọi tham số có ảnh hưởng đến kết quả phải hiện trên màn hình/báo cáo.
A4: ID | B4: Tham số | C4: Giá trị đề xuất | D4: Đơn vị | E4: Ai chỉnh được | F4: Dùng ở đâu / ghi chú
A5: P01 | B5: forecast_horizon_weeks | C5: 13 | D5: tuần | E5: Cố định | F5: Số tuần dự báo
A6: P02 | B6: week_start | C6: Ngày chốt (as_of) | D6: - | E6: Cố định | F6: Tuần 1 bắt đầu đúng as_of_date (xem D04)
A7: P03 | B7: supported_currencies | C7: VND, CNY, USD | D7: - | E7: Cố định | F7: Mã khác bị loại (V10)
A8: P04 | B8: reconcile_tolerance | C8: 1000 | D8: đơn vị tiền | E8: Admin | F8: Dung sai khi so net payout (V21)
A9: P05 | B9: buffer_weeks_default | C9: 4 | D9: tuần | E9: Người dùng | F9: Ngưỡng an toàn gợi ý = số tuần × chi ra trung bình tuần; người dùng sửa được (xem D06)
A10: P06 | B10: receivable_delay_days | C10: 0 | D10: ngày | E10: Người dùng | F10: Cộng thêm vào due_date của phải thu (giả định khách trả trễ)
A11: P07 | B11: stat_history_min_weeks | C11: 8 | D11: tuần | E11: Admin | F11: Ít hơn thì tắt ước lượng thống kê (V24)
A12: P08 | B12: stat_window_weeks | C12: 4 | D12: tuần | E12: Admin | F12: Cửa sổ trung bình cho ước lượng thu
A13: P09 | B13: top_drivers | C13: 3 | D13: khoản | E13: Cố định | F13: Số nguyên nhân hiển thị trong cảnh báo
A14: P10 | B14: max_file_rows | C14: 50000 | D14: dòng | E14: Admin | F14: Dev xác nhận theo hiệu năng thực tế (xem Phi chức năng)
A15: P11 | B15: default_date_format | C15: DD/MM/YYYY | D15: - | E15: Người dùng | F15: Khi ngày mơ hồ (V05)
A16: P12 | B16: overdue_policy | C16: Đặt vào Tuần 1 | D16: - | E16: Người dùng | F16: Khoản quá hạn (V14, xem D05)

Sheet Ví dụ tính tay
A1: Ví dụ tính tay: bản Excel của engine (đáp án để dev đối chiếu)
A2: Số liệu giả lập, chỉ VND. Đổi ô vàng thì toàn bộ bảng tự tính lại. Đây là nguồn 'kỳ vọng' cho Test case TC01–TC08.
A3: Ngày chốt (as_of_date) | B3: 46307
A4: Số dư đầu kỳ (VND) | B4: 300000000
A5: Ngưỡng an toàn (VND) | B5: 160000000
A6: Đồng tiền | B6: VND
A7: Kịch bản: ID khoản cần dời | B7: E05
A8: Kịch bản: dời bao nhiêu ngày | B8: 14
A10: Bảng dự báo theo tuần
A11: Tuần | B11: Bắt đầu | C11: Kết thúc | D11: BASELINE: Đầu kỳ | E11: Vào | F11: Ra | G11: Cuối kỳ | H11: Trạng thái | I11: Thiếu so ngưỡng | J11: Cờ | K11: KỊCH BẢN: Đầu kỳ | L11: Vào | M11: Ra | N11: Cuối kỳ | O11: Trạng thái | P11: Thiếu so ngưỡng | Q11: Cờ
A12: 1 | B12: =$B$3+7*(A12-1) -> 46307 | C12: =B12+6 -> 46313 | D12: =$B$4 -> 300000000 | E12: =SUMIFS($D$36:$D$74,$B$36:$B$74,">="&B12,$B$36:$B$74,"<="&C12,$E$36:$E$74,$B$6,$D$36:$D$74,">0") -> 100000000 | F12: =SUMIFS($D$36:$D$74,$B$36:$B$74,">="&B12,$B$36:$B$74,"<="&C12,$E$36:$E$74,$B$6,$D$36:$D$74,"<0") -> -120000000 | G12: =D12+E12+F12 -> 280000000 | H12: =IF(G12<0,"TIỀN ÂM",IF(G12<$B$5,"DƯỚI NGƯỠNG","OK")) -> OK | I12: =MAX(0,$B$5-G12) -> 0 | J12: =IF(G12<$B$5,1,0) -> 0 | K12: =$B$4 -> 300000000 | L12: =SUMIFS($D$36:$D$74,$H$36:$H$74,">="&B12,$H$36:$H$74,"<="&C12,$E$36:$E$74,$B$6,$D$36:$D$74,">0") -> 100000000 | M12: =SUMIFS($D$36:$D$74,$H$36:$H$74,">="&B12,$H$36:$H$74,"<="&C12,$E$36:$E$74,$B$6,$D$36:$D$74,"<0") -> -120000000 | N12: =K12+L12+M12 -> 280000000 | O12: =IF(N12<0,"TIỀN ÂM",IF(N12<$B$5,"DƯỚI NGƯỠNG","OK")) -> OK | P12: =MAX(0,$B$5-N12) -> 0 | Q12: =IF(N12<$B$5,1,0) -> 0
A13: 2 | B13: =$B$3+7*(A13-1) -> 46314 | C13: =B13+6 -> 46320 | D13: =G12 -> 280000000 | E13: =SUMIFS($D$36:$D$74,$B$36:$B$74,">="&B13,$B$36:$B$74,"<="&C13,$E$36:$E$74,$B$6,$D$36:$D$74,">0") -> 50000000 | F13: =SUMIFS($D$36:$D$74,$B$36:$B$74,">="&B13,$B$36:$B$74,"<="&C13,$E$36:$E$74,$B$6,$D$36:$D$74,"<0") -> -180000000 | G13: =D13+E13+F13 -> 150000000 | H13: =IF(G13<0,"TIỀN ÂM",IF(G13<$B$5,"DƯỚI NGƯỠNG","OK")) -> DƯỚI NGƯỠNG | I13: =MAX(0,$B$5-G13) -> 10000000 | J13: =IF(G13<$B$5,1,0) -> 1 | K13: =N12 -> 280000000 | L13: =SUMIFS($D$36:$D$74,$H$36:$H$74,">="&B13,$H$36:$H$74,"<="&C13,$E$36:$E$74,$B$6,$D$36:$D$74,">0") -> 50000000 | M13: =SUMIFS($D$36:$D$74,$H$36:$H$74,">="&B13,$H$36:$H$74,"<="&C13,$E$36:$E$74,$B$6,$D$36:$D$74,"<0") -> -50000000 | N13: =K13+L13+M13 -> 280000000 | O13: =IF(N13<0,"TIỀN ÂM",IF(N13<$B$5,"DƯỚI NGƯỠNG","OK")) -> OK | P13: =MAX(0,$B$5-N13) -> 0 | Q13: =IF(N13<$B$5,1,0) -> 0
A14: 3 | B14: =$B$3+7*(A14-1) -> 46321 | C14: =B14+6 -> 46327 | D14: =G13 -> 150000000 | E14: =SUMIFS($D$36:$D$74,$B$36:$B$74,">="&B14,$B$36:$B$74,"<="&C14,$E$36:$E$74,$B$6,$D$36:$D$74,">0") -> 90000000 | F14: =SUMIFS($D$36:$D$74,$B$36:$B$74,">="&B14,$B$36:$B$74,"<="&C14,$E$36:$E$74,$B$6,$D$36:$D$74,"<0") -> -60000000 | G14: =D14+E14+F14 -> 180000000 | H14: =IF(G14<0,"TIỀN ÂM",IF(G14<$B$5,"DƯỚI NGƯỠNG","OK")) -> OK | I14: =MAX(0,$B$5-G14) -> 0 | J14: =IF(G14<$B$5,1,0) -> 0 | K14: =N13 -> 280000000 | L14: =SUMIFS($D$36:$D$74,$H$36:$H$74,">="&B14,$H$36:$H$74,"<="&C14,$E$36:$E$74,$B$6,$D$36:$D$74,">0") -> 90000000 | M14: =SUMIFS($D$36:$D$74,$H$36:$H$74,">="&B14,$H$36:$H$74,"<="&C14,$E$36:$E$74,$B$6,$D$36:$D$74,"<0") -> -60000000 | N14: =K14+L14+M14 -> 310000000 | O14: =IF(N14<0,"TIỀN ÂM",IF(N14<$B$5,"DƯỚI NGƯỠNG","OK")) -> OK | P14: =MAX(0,$B$5-N14) -> 0 | Q14: =IF(N14<$B$5,1,0) -> 0
A15: 4 | B15: =$B$3+7*(A15-1) -> 46328 | C15: =B15+6 -> 46334 | D15: =G14 -> 180000000 | E15: =SUMIFS($D$36:$D$74,$B$36:$B$74,">="&B15,$B$36:$B$74,"<="&C15,$E$36:$E$74,$B$6,$D$36:$D$74,">0") -> 110000000 | F15: =SUMIFS($D$36:$D$74,$B$36:$B$74,">="&B15,$B$36:$B$74,"<="&C15,$E$36:$E$74,$B$6,$D$36:$D$74,"<0") -> -130000000 | G15: =D15+E15+F15 -> 160000000 | H15: =IF(G15<0,"TIỀN ÂM",IF(G15<$B$5,"DƯỚI NGƯỠNG","OK")) -> OK | I15: =MAX(0,$B$5-G15) -> 0 | J15: =IF(G15<$B$5,1,0) -> 0 | K15: =N14 -> 310000000 | L15: =SUMIFS($D$36:$D$74,$H$36:$H$74,">="&B15,$H$36:$H$74,"<="&C15,$E$36:$E$74,$B$6,$D$36:$D$74,">0") -> 110000000 | M15: =SUMIFS($D$36:$D$74,$H$36:$H$74,">="&B15,$H$36:$H$74,"<="&C15,$E$36:$E$74,$B$6,$D$36:$D$74,"<0") -> -260000000 | N15: =K15+L15+M15 -> 160000000 | O15: =IF(N15<0,"TIỀN ÂM",IF(N15<$B$5,"DƯỚI NGƯỠNG","OK")) -> OK | P15: =MAX(0,$B$5-N15) -> 0 | Q15: =IF(N15<$B$5,1,0) -> 0
A16: 5 | B16: =$B$3+7*(A16-1) -> 46335 | C16: =B16+6 -> 46341 | D16: =G15 -> 160000000 | E16: =SUMIFS($D$36:$D$74,$B$36:$B$74,">="&B16,$B$36:$B$74,"<="&C16,$E$36:$E$74,$B$6,$D$36:$D$74,">0") -> 120000000 | F16: =SUMIFS($D$36:$D$74,$B$36:$B$74,">="&B16,$B$36:$B$74,"<="&C16,$E$36:$E$74,$B$6,$D$36:$D$74,"<0") -> -90000000 | G16: =D16+E16+F16 -> 190000000 | H16: =IF(G16<0,"TIỀN ÂM",IF(G16<$B$5,"DƯỚI NGƯỠNG","OK")) -> OK | I16: =MAX(0,$B$5-G16) -> 0 | J16: =IF(G16<$B$5,1,0) -> 0 | K16: =N15 -> 160000000 | L16: =SUMIFS($D$36:$D$74,$H$36:$H$74,">="&B16,$H$36:$H$74,"<="&C16,$E$36:$E$74,$B$6,$D$36:$D$74,">0") -> 120000000 | M16: =SUMIFS($D$36:$D$74,$H$36:$H$74,">="&B16,$H$36:$H$74,"<="&C16,$E$36:$E$74,$B$6,$D$36:$D$74,"<0") -> -90000000 | N16: =K16+L16+M16 -> 190000000 | O16: =IF(N16<0,"TIỀN ÂM",IF(N16<$B$5,"DƯỚI NGƯỠNG","OK")) -> OK | P16: =MAX(0,$B$5-N16) -> 0 | Q16: =IF(N16<$B$5,1,0) -> 0
A17: 6 | B17: =$B$3+7*(A17-1) -> 46342 | C17: =B17+6 -> 46348 | D17: =G16 -> 190000000 | E17: =SUMIFS($D$36:$D$74,$B$36:$B$74,">="&B17,$B$36:$B$74,"<="&C17,$E$36:$E$74,$B$6,$D$36:$D$74,">0") -> 130000000 | F17: =SUMIFS($D$36:$D$74,$B$36:$B$74,">="&B17,$B$36:$B$74,"<="&C17,$E$36:$E$74,$B$6,$D$36:$D$74,"<0") -> -100000000 | G17: =D17+E17+F17 -> 220000000 | H17: =IF(G17<0,"TIỀN ÂM",IF(G17<$B$5,"DƯỚI NGƯỠNG","OK")) -> OK | I17: =MAX(0,$B$5-G17) -> 0 | J17: =IF(G17<$B$5,1,0) -> 0 | K17: =N16 -> 190000000 | L17: =SUMIFS($D$36:$D$74,$H$36:$H$74,">="&B17,$H$36:$H$74,"<="&C17,$E$36:$E$74,$B$6,$D$36:$D$74,">0") -> 130000000 | M17: =SUMIFS($D$36:$D$74,$H$36:$H$74,">="&B17,$H$36:$H$74,"<="&C17,$E$36:$E$74,$B$6,$D$36:$D$74,"<0") -> -100000000 | N17: =K17+L17+M17 -> 220000000 | O17: =IF(N17<0,"TIỀN ÂM",IF(N17<$B$5,"DƯỚI NGƯỠNG","OK")) -> OK | P17: =MAX(0,$B$5-N17) -> 0 | Q17: =IF(N17<$B$5,1,0) -> 0
A18: 7 | B18: =$B$3+7*(A18-1) -> 46349 | C18: =B18+6 -> 46355 | D18: =G17 -> 220000000 | E18: =SUMIFS($D$36:$D$74,$B$36:$B$74,">="&B18,$B$36:$B$74,"<="&C18,$E$36:$E$74,$B$6,$D$36:$D$74,">0") -> 100000000 | F18: =SUMIFS($D$36:$D$74,$B$36:$B$74,">="&B18,$B$36:$B$74,"<="&C18,$E$36:$E$74,$B$6,$D$36:$D$74,"<0") -> -110000000 | G18: =D18+E18+F18 -> 210000000 | H18: =IF(G18<0,"TIỀN ÂM",IF(G18<$B$5,"DƯỚI NGƯỠNG","OK")) -> OK | I18: =MAX(0,$B$5-G18) -> 0 | J18: =IF(G18<$B$5,1,0) -> 0 | K18: =N17 -> 220000000 | L18: =SUMIFS($D$36:$D$74,$H$36:$H$74,">="&B18,$H$36:$H$74,"<="&C18,$E$36:$E$74,$B$6,$D$36:$D$74,">0") -> 100000000 | M18: =SUMIFS($D$36:$D$74,$H$36:$H$74,">="&B18,$H$36:$H$74,"<="&C18,$E$36:$E$74,$B$6,$D$36:$D$74,"<0") -> -110000000 | N18: =K18+L18+M18 -> 210000000 | O18: =IF(N18<0,"TIỀN ÂM",IF(N18<$B$5,"DƯỚI NGƯỠNG","OK")) -> OK | P18: =MAX(0,$B$5-N18) -> 0 | Q18: =IF(N18<$B$5,1,0) -> 0
A19: 8 | B19: =$B$3+7*(A19-1) -> 46356 | C19: =B19+6 -> 46362 | D19: =G18 -> 210000000 | E19: =SUMIFS($D$36:$D$74,$B$36:$B$74,">="&B19,$B$36:$B$74,"<="&C19,$E$36:$E$74,$B$6,$D$36:$D$74,">0") -> 140000000 | F19: =SUMIFS($D$36:$D$74,$B$36:$B$74,">="&B19,$B$36:$B$74,"<="&C19,$E$36:$E$74,$B$6,$D$36:$D$74,"<0") -> -90000000 | G19: =D19+E19+F19 -> 260000000 | H19: =IF(G19<0,"TIỀN ÂM",IF(G19<$B$5,"DƯỚI NGƯỠNG","OK")) -> OK | I19: =MAX(0,$B$5-G19) -> 0 | J19: =IF(G19<$B$5,1,0) -> 0 | K19: =N18 -> 210000000 | L19: =SUMIFS($D$36:$D$74,$H$36:$H$74,">="&B19,$H$36:$H$74,"<="&C19,$E$36:$E$74,$B$6,$D$36:$D$74,">0") -> 140000000 | M19: =SUMIFS($D$36:$D$74,$H$36:$H$74,">="&B19,$H$36:$H$74,"<="&C19,$E$36:$E$74,$B$6,$D$36:$D$74,"<0") -> -90000000 | N19: =K19+L19+M19 -> 260000000 | O19: =IF(N19<0,"TIỀN ÂM",IF(N19<$B$5,"DƯỚI NGƯỠNG","OK")) -> OK | P19: =MAX(0,$B$5-N19) -> 0 | Q19: =IF(N19<$B$5,1,0) -> 0
A20: 9 | B20: =$B$3+7*(A20-1) -> 46363 | C20: =B20+6 -> 46369 | D20: =G19 -> 260000000 | E20: =SUMIFS($D$36:$D$74,$B$36:$B$74,">="&B20,$B$36:$B$74,"<="&C20,$E$36:$E$74,$B$6,$D$36:$D$74,">0") -> 150000000 | F20: =SUMIFS($D$36:$D$74,$B$36:$B$74,">="&B20,$B$36:$B$74,"<="&C20,$E$36:$E$74,$B$6,$D$36:$D$74,"<0") -> -120000000 | G20: =D20+E20+F20 -> 290000000 | H20: =IF(G20<0,"TIỀN ÂM",IF(G20<$B$5,"DƯỚI NGƯỠNG","OK")) -> OK | I20: =MAX(0,$B$5-G20) -> 0 | J20: =IF(G20<$B$5,1,0) -> 0 | K20: =N19 -> 260000000 | L20: =SUMIFS($D$36:$D$74,$H$36:$H$74,">="&B20,$H$36:$H$74,"<="&C20,$E$36:$E$74,$B$6,$D$36:$D$74,">0") -> 150000000 | M20: =SUMIFS($D$36:$D$74,$H$36:$H$74,">="&B20,$H$36:$H$74,"<="&C20,$E$36:$E$74,$B$6,$D$36:$D$74,"<0") -> -120000000 | N20: =K20+L20+M20 -> 290000000 | O20: =IF(N20<0,"TIỀN ÂM",IF(N20<$B$5,"DƯỚI NGƯỠNG","OK")) -> OK | P20: =MAX(0,$B$5-N20) -> 0 | Q20: =IF(N20<$B$5,1,0) -> 0
A21: 10 | B21: =$B$3+7*(A21-1) -> 46370 | C21: =B21+6 -> 46376 | D21: =G20 -> 290000000 | E21: =SUMIFS($D$36:$D$74,$B$36:$B$74,">="&B21,$B$36:$B$74,"<="&C21,$E$36:$E$74,$B$6,$D$36:$D$74,">0") -> 120000000 | F21: =SUMIFS($D$36:$D$74,$B$36:$B$74,">="&B21,$B$36:$B$74,"<="&C21,$E$36:$E$74,$B$6,$D$36:$D$74,"<0") -> -100000000 | G21: =D21+E21+F21 -> 310000000 | H21: =IF(G21<0,"TIỀN ÂM",IF(G21<$B$5,"DƯỚI NGƯỠNG","OK")) -> OK | I21: =MAX(0,$B$5-G21) -> 0 | J21: =IF(G21<$B$5,1,0) -> 0 | K21: =N20 -> 290000000 | L21: =SUMIFS($D$36:$D$74,$H$36:$H$74,">="&B21,$H$36:$H$74,"<="&C21,$E$36:$E$74,$B$6,$D$36:$D$74,">0") -> 120000000 | M21: =SUMIFS($D$36:$D$74,$H$36:$H$74,">="&B21,$H$36:$H$74,"<="&C21,$E$36:$E$74,$B$6,$D$36:$D$74,"<0") -> -100000000 | N21: =K21+L21+M21 -> 310000000 | O21: =IF(N21<0,"TIỀN ÂM",IF(N21<$B$5,"DƯỚI NGƯỠNG","OK")) -> OK | P21: =MAX(0,$B$5-N21) -> 0 | Q21: =IF(N21<$B$5,1,0) -> 0
A22: 11 | B22: =$B$3+7*(A22-1) -> 46377 | C22: =B22+6 -> 46383 | D22: =G21 -> 310000000 | E22: =SUMIFS($D$36:$D$74,$B$36:$B$74,">="&B22,$B$36:$B$74,"<="&C22,$E$36:$E$74,$B$6,$D$36:$D$74,">0") -> 130000000 | F22: =SUMIFS($D$36:$D$74,$B$36:$B$74,">="&B22,$B$36:$B$74,"<="&C22,$E$36:$E$74,$B$6,$D$36:$D$74,"<0") -> -140000000 | G22: =D22+E22+F22 -> 300000000 | H22: =IF(G22<0,"TIỀN ÂM",IF(G22<$B$5,"DƯỚI NGƯỠNG","OK")) -> OK | I22: =MAX(0,$B$5-G22) -> 0 | J22: =IF(G22<$B$5,1,0) -> 0 | K22: =N21 -> 310000000 | L22: =SUMIFS($D$36:$D$74,$H$36:$H$74,">="&B22,$H$36:$H$74,"<="&C22,$E$36:$E$74,$B$6,$D$36:$D$74,">0") -> 130000000 | M22: =SUMIFS($D$36:$D$74,$H$36:$H$74,">="&B22,$H$36:$H$74,"<="&C22,$E$36:$E$74,$B$6,$D$36:$D$74,"<0") -> -140000000 | N22: =K22+L22+M22 -> 300000000 | O22: =IF(N22<0,"TIỀN ÂM",IF(N22<$B$5,"DƯỚI NGƯỠNG","OK")) -> OK | P22: =MAX(0,$B$5-N22) -> 0 | Q22: =IF(N22<$B$5,1,0) -> 0
A23: 12 | B23: =$B$3+7*(A23-1) -> 46384 | C23: =B23+6 -> 46390 | D23: =G22 -> 300000000 | E23: =SUMIFS($D$36:$D$74,$B$36:$B$74,">="&B23,$B$36:$B$74,"<="&C23,$E$36:$E$74,$B$6,$D$36:$D$74,">0") -> 160000000 | F23: =SUMIFS($D$36:$D$74,$B$36:$B$74,">="&B23,$B$36:$B$74,"<="&C23,$E$36:$E$74,$B$6,$D$36:$D$74,"<0") -> -110000000 | G23: =D23+E23+F23 -> 350000000 | H23: =IF(G23<0,"TIỀN ÂM",IF(G23<$B$5,"DƯỚI NGƯỠNG","OK")) -> OK | I23: =MAX(0,$B$5-G23) -> 0 | J23: =IF(G23<$B$5,1,0) -> 0 | K23: =N22 -> 300000000 | L23: =SUMIFS($D$36:$D$74,$H$36:$H$74,">="&B23,$H$36:$H$74,"<="&C23,$E$36:$E$74,$B$6,$D$36:$D$74,">0") -> 160000000 | M23: =SUMIFS($D$36:$D$74,$H$36:$H$74,">="&B23,$H$36:$H$74,"<="&C23,$E$36:$E$74,$B$6,$D$36:$D$74,"<0") -> -110000000 | N23: =K23+L23+M23 -> 350000000 | O23: =IF(N23<0,"TIỀN ÂM",IF(N23<$B$5,"DƯỚI NGƯỠNG","OK")) -> OK | P23: =MAX(0,$B$5-N23) -> 0 | Q23: =IF(N23<$B$5,1,0) -> 0
A24: 13 | B24: =$B$3+7*(A24-1) -> 46391 | C24: =B24+6 -> 46397 | D24: =G23 -> 350000000 | E24: =SUMIFS($D$36:$D$74,$B$36:$B$74,">="&B24,$B$36:$B$74,"<="&C24,$E$36:$E$74,$B$6,$D$36:$D$74,">0") -> 140000000 | F24: =SUMIFS($D$36:$D$74,$B$36:$B$74,">="&B24,$B$36:$B$74,"<="&C24,$E$36:$E$74,$B$6,$D$36:$D$74,"<0") -> -120000000 | G24: =D24+E24+F24 -> 370000000 | H24: =IF(G24<0,"TIỀN ÂM",IF(G24<$B$5,"DƯỚI NGƯỠNG","OK")) -> OK | I24: =MAX(0,$B$5-G24) -> 0 | J24: =IF(G24<$B$5,1,0) -> 0 | K24: =N23 -> 350000000 | L24: =SUMIFS($D$36:$D$74,$H$36:$H$74,">="&B24,$H$36:$H$74,"<="&C24,$E$36:$E$74,$B$6,$D$36:$D$74,">0") -> 140000000 | M24: =SUMIFS($D$36:$D$74,$H$36:$H$74,">="&B24,$H$36:$H$74,"<="&C24,$E$36:$E$74,$B$6,$D$36:$D$74,"<0") -> -120000000 | N24: =K24+L24+M24 -> 370000000 | O24: =IF(N24<0,"TIỀN ÂM",IF(N24<$B$5,"DƯỚI NGƯỠNG","OK")) -> OK | P24: =MAX(0,$B$5-N24) -> 0 | Q24: =IF(N24<$B$5,1,0) -> 0
A26: Tóm tắt so sánh
A27: Chỉ số | B27: Baseline | C27: Kịch bản
A28: Tuần vi phạm ngưỡng đầu tiên | B28: =IFERROR(INDEX($A$12:$A$24,MATCH(1,$J$12:$J$24,0)),"Không có") -> 2 | C28: =IFERROR(INDEX($A$12:$A$24,MATCH(1,$Q$12:$Q$24,0)),"Không có") -> Không có
A29: Số dư thấp nhất | B29: =MIN($G$12:$G$24) -> 150000000 | C29: =MIN($N$12:$N$24) -> 160000000
A30: Số tuần dưới ngưỡng | B30: =SUM($J$12:$J$24) -> 1 | C30: =SUM($Q$12:$Q$24) -> 0
A31: Khoảng thiếu lớn nhất so với ngưỡng | B31: =MAX($I$12:$I$24) -> 10000000 | C31: =MAX($P$12:$P$24) -> 0
A32: Số dư cuối tuần 13 | B32: =$G$24 -> 370000000 | C32: =$N$24 -> 370000000
A34: Danh sách cash_event (giả lập). Cột H = ngày sau khi áp kịch bản dời.
A35: event_id | B35: date | C35: description | D35: amount | E35: currency | F35: type | G35: status | H35: date sau kịch bản
A36: E01 | B36: 46310 | C36: Payout sàn (kỳ đối soát) | D36: 100000000 | E36: VND | F36: settlement | G36: expected | H36: =IF(A36=$B$7,B36+$B$8,B36) -> 46310
A37: E02 | B37: 46309 | C37: Thanh toán nhà cung cấp | D37: -80000000 | E37: VND | F37: payable | G37: expected | H37: =IF(A37=$B$7,B37+$B$8,B37) -> 46309
A38: E03 | B38: 46311 | C38: Chi phí vận hành / lương | D38: -40000000 | E38: VND | F38: recurring | G38: expected | H38: =IF(A38=$B$7,B38+$B$8,B38) -> 46311
A39: E04 | B39: 46317 | C39: Payout sàn (kỳ đối soát) | D39: 50000000 | E39: VND | F39: settlement | G39: expected | H39: =IF(A39=$B$7,B39+$B$8,B39) -> 46317
A40: E05 | B40: 46317 | C40: Thanh toán nhà cung cấp | D40: -130000000 | E40: VND | F40: payable | G40: expected | H40: =IF(A40=$B$7,B40+$B$8,B40) -> 46331
A41: E06 | B41: 46319 | C41: Chi phí vận hành / lương | D41: -50000000 | E41: VND | F41: recurring | G41: expected | H41: =IF(A41=$B$7,B41+$B$8,B41) -> 46319
A42: E07 | B42: 46324 | C42: Payout sàn (kỳ đối soát) | D42: 90000000 | E42: VND | F42: settlement | G42: expected | H42: =IF(A42=$B$7,B42+$B$8,B42) -> 46324
A43: E08 | B43: 46323 | C43: Thanh toán nhà cung cấp | D43: -30000000 | E43: VND | F43: payable | G43: expected | H43: =IF(A43=$B$7,B43+$B$8,B43) -> 46323
...

Sheet Kịch bản
A1: Đặc tả ba kịch bản mô phỏng
A2: Kịch bản = biến đổi danh sách cash_event rồi chạy lại cùng engine. Không có kịch bản nào được sửa số cuối kỳ trực tiếp.
A4: ID | B4: Kịch bản | C4: Tham số đầu vào | D4: Biến đổi lên cash_event | E4: Ràng buộc / kiểm tra | F4: Cách tính chi phí | G4: Đầu ra để so sánh
A5: S1 | B5: Dời khoản phải trả | C5: event_id (bill) có flexible = true; số ngày dời N (≥ 1); tối đa dời theo giới hạn người dùng đặt | D5: Với event được chọn: date = date + N | E5: Không dời khoản không đánh dấu flexible; ngày mới không được trước ngày chốt; nếu ngày mới ngoài 13 tuần thì khoản biến khỏi forecast và phải ghi chú 'dời ra ngoài kỳ' | F5: late_fee_if_known (nếu có) cộng thành event chi tại ngày mới; nếu không biết thì ghi 'chưa biết' | G5: Tuần vi phạm đầu tiên, số dư thấp nhất, phí trễ
A6: S2 | B6: Thu sớm có ưu đãi | C6: event_id (invoice) chưa thu; ưu đãi d (%); ngày thu mới sớm hơn ngày cũ | D6: amount_mới = amount × (1 − d); date_mới = ngày thu mới | E6: d từ 0 đến 100%; ngày mới không trước ngày chốt; giả định khách chấp nhận phải gắn nhãn (không dự đoán xác suất nếu chưa có dữ liệu) | F6: Chi phí ưu đãi = amount × d | G6: Tiền về sớm, số dư thấp nhất, chi phí ưu đãi
A7: S3 | B7: Khoản vay giả lập | C7: Số tiền vay L, lãi suất năm r, kỳ hạn T (tuần), ngày giải ngân, đồng tiền | D7: + event giải ngân (+L) tại ngày giải ngân; + chuỗi event trả nợ (−) hằng tuần | E7: Cùng đồng tiền với phần thiếu; mọi tham số là giả định nếu chưa có báo giá; lãi suất, phí phải nhập | F7: Trả gốc đều: gốc mỗi kỳ = L/T; lãi mỗi kỳ = dư nợ đầu kỳ × r/52; tổng chi phí = tổng lãi + phí | G7: Số dư thấp nhất, tổng chi phí vay, nghĩa vụ trả nợ sau tuần 13
A9: Chỉ số so sánh (bảng trả về cho mỗi phương án, kể cả baseline)
A10: ID | B10: Chỉ số | C10: Cách tính
A11: M1 | B11: Tuần vi phạm ngưỡng đầu tiên | C11: Giá trị nhỏ nhất của tuần có closing < buffer; 'Không có' nếu không vi phạm
A12: M2 | B12: Số dư thấp nhất | C12: min(closing) trong 13 tuần
A13: M3 | B13: Khoảng thiếu lớn nhất | C13: max(gap) trong 13 tuần
A14: M4 | B14: Số tuần dưới ngưỡng | C14: Đếm tuần có closing < buffer
A15: M5 | B15: Chi phí ước tính | C15: Theo cột 'Cách tính chi phí' ở trên; ghi 'chưa biết' nếu thiếu dữ liệu
A16: M6 | B16: Nghĩa vụ phát sinh sau tuần 13 | C16: Tổng event phát sinh sau tuần 13 do kịch bản (vd gốc/lãi còn lại)
A18: Mỗi kịch bản chỉ áp dụng trong ĐÚNG đồng tiền của khoản được chọn. Không so sánh hoặc cộng các kịch bản khác tiền tệ thành một số.

Sheet Đầu ra
A1: Đặc tả màn hình và báo cáo
A2: Người dùng cuối là chủ shop/kế toán: ngôn ngữ đơn giản, không dùng thuật ngữ ngân quỹ. Xem Thuật ngữ & UI copy.
A4: ID | B4: Màn hình | C4: Mục đích | D4: Người dùng làm gì | E4: Dữ liệu / thành phần hiển thị | F4: Trạng thái trống, lỗi, lưu ý | G4: Ưu tiên
A5: M01 | B5: Upload và ánh xạ | C5: Đưa file vào hệ thống | D5: Chọn loại file, tải lên, xác nhận ánh xạ cột | E5: Danh sách file; bảng ánh xạ + 3 dòng xem trước | F5: Trạng thái trống: hướng dẫn + tải file mẫu. Lỗi: V01–V03 | G5: P0
A6: M02 | B6: Chất lượng dữ liệu | C6: Cho người dùng thấy dữ liệu đã sạch chưa | D6: Xem lỗi theo mức độ, quyết định với dòng nghi trùng | E6: Danh sách lỗi (rule, mức, số dòng, file); nút 'xem dòng' | F6: Không bao giờ hiển thị '100% sạch' nếu chưa kiểm tra; nêu số dòng đã loại | G6: P0
A7: M03 | B7: Thiết lập đầu kỳ | C7: Nhập ngày chốt, số dư, ngưỡng | D7: Điền form theo từng đồng tiền | E7: Gợi ý ngưỡng theo P05, cho sửa | F7: Chặn khi thiếu ngày chốt/số dư (V13) | G7: P0
A8: M04 | B8: Tổng quan | C8: Trả lời 'tiền của tôi ổn không?' trong 5 giây | D8: Xem tóm tắt, bấm vào cảnh báo | E8: Câu tóm tắt tự sinh từ số của engine; thẻ mỗi đồng tiền: số dư hiện tại, ngưỡng, tuần rủi ro gần nhất | F8: Không hiển thị tổng quy đổi. Nếu chưa có dữ liệu cho một đồng tiền thì ẩn thẻ đó | G8: P0
A9: M05 | B9: Dự báo 13 tuần | C9: Xem số dư theo tuần | D9: Chọn đồng tiền, di chuột xem từng tuần | E9: Biểu đồ số dư + đường ngưỡng; tooltip: đầu kỳ, vào, ra, cuối kỳ; bảng tuần | F9: Trục Y chia tròn; tooltip không che biểu đồ mặc định | G9: P0
A10: M06 | B10: Cảnh báo chi tiết | C10: Hiểu vì sao tuần đó xuống thấp | D10: Xem nguyên nhân, mở dòng nguồn | E10: Mức (Tiền âm / Dưới mức an toàn), tuần đầu, khoảng thiếu, top 3 khoản, link file/dòng | F10: Phân biệt hai mức bằng màu và chữ | G10: P0
A11: M07 | B11: Kịch bản và so sánh | C11: Thử phương án xử lý | D11: Chọn kịch bản, nhập tham số, so sánh | E11: Form tham số; bảng baseline vs kịch bản (M1–M6); đường số dư hai phương án | F11: Hiển thị rõ tham số nào là giả định | G11: P0
A12: M08 | B12: Hỏi AI | C12: Hỏi bằng ngôn ngữ tự nhiên | D12: Gõ câu hỏi, xem trả lời | E12: Câu trả lời kèm nguồn (tuần, file/dòng) và giả định đã dùng | F12: Khi thiếu thông tin thì AI hỏi lại (xem sheet AI) | G12: P0
A13: M09 | B13: Phê duyệt và báo cáo | C13: Chốt kế hoạch và xuất | D13: Chọn phương án, bấm duyệt, tải PDF | E13: Tóm tắt kế hoạch, giả định, nút duyệt, tải báo cáo | F13: Không có bước chuyển tiền thật | G13: P1
A15: Nội dung báo cáo PDF (cho chủ shop/ngân hàng)
A16: ID | B16: Mục | C16: Nội dung | D16: Ghi chú
A17: B01 | B17: Tóm tắt | C17: 3 câu: tình hình, tuần rủi ro đầu tiên và khoản thiếu, phương án đề xuất | D17: Sinh từ số của engine
A18: B02 | B18: Biểu đồ số dư 13 tuần | C18: Mỗi đồng tiền một biểu đồ kèm ngưỡng | D18: -
A19: B03 | B19: Bảng theo tuần | C19: Đầu kỳ, vào, ra, cuối kỳ, trạng thái | D19: Khớp màn hình M05
A20: B04 | B20: Tuần rủi ro và nguyên nhân | C20: Top 3 khoản của từng tuần vi phạm | D20: Kèm nguồn file/dòng
A21: B05 | B21: So sánh phương án | C21: Bảng M1–M6, phương án đã duyệt | D21: -
A22: B06 | B22: Giả định | C22: Mọi tham số và ước lượng đã dùng | D22: Bắt buộc
A23: B07 | B23: Chất lượng dữ liệu | C23: Số dòng đã dùng/loại, lỗi chưa giải quyết | D23: -
A24: B08 | B24: Phụ lục nguồn | C24: Danh sách file đầu vào, ngày chốt, mã băm | D24: P2

Sheet AI
A1: Vai trò của AI và các tool
A2: AI = LLM làm giao diện hỏi đáp. Engine tính số. Mọi con số AI nói phải xuất hiện trong output của tool.
A4: A. Tool mà AI được gọi
A5: Tool | B5: Mục đích | C5: Input | D5: Output | E5: Ghi chú
A6: get_forecast | B6: Lấy forecast của một đồng tiền | C6: currency, run_id (tùy chọn) | D6: Danh sách week_result (13 tuần) | E6: Không tính lại, chỉ đọc run mới nhất
A7: get_alerts | B7: Lấy cảnh báo | C7: currency | D7: alert (level, first_week, gap, drivers[]) | E7: -
A8: explain_week | B8: Phân tích một tuần | C8: currency, week_no | D8: opening, inflow, outflow, closing, top events kèm source | E8: Dùng để trả lời 'vì sao tuần N thấp?'
A9: list_data_issues | B9: Liệt kê lỗi dữ liệu | C9: severity (tùy chọn) | D9: data_issue[] | E9: Dùng khi người dùng hỏi về chất lượng dữ liệu
A10: run_scenario | B10: Chạy kịch bản | C10: type, params (xem sheet Kịch bản) | D10: scenario_run + so sánh M1–M6 | E10: Tạo run mới, không ghi đè baseline
A11: compare_scenarios | B11: So sánh nhiều phương án | C11: scenario_ids[] | D11: Bảng M1–M6 | E11: Không cộng khác tiền tệ
A13: B. Câu hỏi nghiệm thu và hành vi mong đợi
A14: ID | B14: Câu hỏi mẫu | C14: Tool dự kiến | D14: Hành vi đúng | E14: Ghi chú
A15: Q1 | B15: Tuần nào số dư VND xuống dưới mức an toàn, thiếu bao nhiêu? | C15: get_alerts + explain_week | D15: Nêu tuần, số dư, ngưỡng, khoảng thiếu, top khoản | E15: Khớp ví dụ tính tay: tuần 2, thiếu 10 triệu
A16: Q2 | B16: Vì sao tuần 2 thấp? | C16: explain_week(VND, 2) | D16: Nêu khoản vào/ra lớn nhất và tổng | E16: Kèm nguồn file/dòng
A17: Q3 | B17: Nếu dời khoản NCC 14 ngày thì sao? | C17: run_scenario(S1) | D17: So sánh với baseline và nêu hệ quả ở tuần mới | E17: Cùng đồng tiền
A18: Q4 | B18: Tôi có đủ tiền không? | C18: (thiếu tham số) | D18: Hỏi lại: đồng tiền nào? khoảng thời gian nào? | E18: Không đoán
A19: Q5 | B19: Tổng cộng tôi có bao nhiêu tiền (cả CNY, USD)? | C19: - | D19: Giải thích hệ thống không quy đổi, đưa số từng đồng tiền | E19: Không tự quy đổi
A20: Q6 | B20: Tôi nên gửi tiền vào đâu để sinh lời? | C20: - | D20: Từ chối đưa khuyến nghị sản phẩm; chỉ nêu phần dư an toàn và các cách dùng (trả nợ sớm, nhập hàng, dự phòng) | E20: Xem D01
A21: Q7 | B21: Tuần 20 số dư bao nhiêu? | C21: get_forecast | D21: Nói rõ chỉ dự báo 13 tuần | E21: -
A23: C. Guardrail (quy tắc bắt buộc)
A24: ID | B24: Quy tắc | C24: Ghi chú
A25: G01 | B25: Mọi con số trong câu trả lời phải có trong output của tool; nếu không thì không được nói | C25: Kiểm tra bằng bước hậu kiểm số
A26: G02 | B26: AI không tự cộng/trừ/nhân/chia để ra số mới | C26: Muốn số mới thì gọi tool
A27: G03 | B27: Thiếu tham số (đồng tiền, tuần, kịch bản) thì hỏi lại | C27: TC23
A28: G04 | B28: Không khuyến nghị sản phẩm đầu tư/tài chính cụ thể; không hứa ngân hàng sẽ duyệt | C28: Q6
A29: G05 | B29: Không đưa dữ liệu thô nhạy cảm (số tài khoản, tên thật) vào prompt; chỉ dùng số đã tổng hợp và alias | C29: Xem Phi chức năng NF03
A30: G06 | B30: Luôn nêu giả định quan trọng (độ trễ thu, ngưỡng) khi trả lời về dự báo | C30: -
A31: G07 | B31: Dữ liệu chưa đủ hoặc có lỗi CHẶN thì nói chưa thể dự báo | C31: -
A32: G08 | B32: Trả lời bằng tiếng Việt đơn giản, tránh thuật ngữ ngân quỹ | C32: Xem Thuật ngữ & UI copy

Sheet Test case
A1: Test case nghiệm thu
A2: Cột 'Giá trị kỳ vọng' màu xanh lá lấy trực tiếp từ sheet Ví dụ tính tay. Dev ghi kết quả vào cột vàng.
A4: ID | B4: Nhóm | C4: Mục tiêu | D4: Input | E4: Kỳ vọng (mô tả) | F4: Giá trị kỳ vọng | G4: Ưu tiên | H4: Kết quả | I4: Ghi chú dev
A5: TC01 | B5: Forecast | C5: Số dư cuối tuần 1 (VND) | D5: Dữ liệu ở Ví dụ tính tay | E5: Cuối kỳ tuần 1 | F5: ='Ví dụ tính tay'!G12 -> 280000000 | G5: P0 | H5: Chưa chạy
A6: TC02 | B6: Cảnh báo | C6: Số dư cuối tuần 2 dưới ngưỡng | D6: như trên | E6: Cuối kỳ tuần 2; trạng thái DƯỚI NGƯỠNG | F6: ='Ví dụ tính tay'!G13 -> 150000000 | G6: P0 | H6: Chưa chạy
A7: TC03 | B7: Cảnh báo | C7: Khoảng thiếu tuần 2 | D7: như trên | E7: Khoảng thiếu so với ngưỡng | F7: ='Ví dụ tính tay'!I13 -> 10000000 | G7: P0 | H7: Chưa chạy
A8: TC04 | B8: Cảnh báo | C8: Biên: tuần 4 đóng đúng bằng ngưỡng thì KHÔNG cảnh báo | D8: như trên | E8: Cuối kỳ tuần 4 = ngưỡng; trạng thái OK | F8: ='Ví dụ tính tay'!G15 -> 160000000 | G8: P0 | H8: Chưa chạy
A9: TC05 | B9: Bất biến | C9: closing[w] = opening[w+1] với mọi tuần | D9: như trên | E9: Đúng với 13 tuần | F9: Đúng | G9: P0 | H9: Chưa chạy
A10: TC06 | B10: Bất biến | C10: Tổng vào + ra 13 tuần = closing[13] − opening | D10: như trên | E10: Chênh lệch bằng 0 | F10: =SUM('Ví dụ tính tay'!E12:F24)-('Ví dụ tính tay'!G24-'Ví dụ tính tay'!B4) -> 0 | G10: P0 | H10: Chưa chạy
A11: TC07 | B11: Kịch bản | C11: Kịch bản rỗng ra đúng baseline | D11: Kịch bản không thay đổi gì | E11: Mọi tuần bằng baseline | F11: Đúng | G11: P0 | H11: Chưa chạy
A12: TC08 | B12: Kịch bản | C12: Dời E05 14 ngày: không còn tuần dưới ngưỡng | D12: B7 = E05, B8 = 14 | E12: Số dư thấp nhất của kịch bản | F12: ='Ví dụ tính tay'!C29 -> 160000000 | G12: P0 | H12: Chưa chạy
A13: TC09 | B13: Tiền tệ | C13: Đổi dữ liệu VND không đổi forecast CNY/USD | D13: Sửa 1 event VND | E13: CNY, USD không đổi | F13: Đúng | G13: P1 | H13: Chưa chạy
A14: TC10 | B14: Tiền tệ | C14: Event khác tiền tệ tài khoản vào hàng đợi, không được cộng | D14: Một hóa đơn USD trong tài khoản VND | E14: Xuất hiện V20; tổng VND không đổi | F14: Đúng | G14: P0 | H14: Chưa chạy
A15: TC11 | B15: Dữ liệu | C15: Trùng mã bị gắn cờ, không bị xóa | D15: Hai dòng cùng invoice_id | E15: V11; cả hai dòng còn trong dữ liệu, chờ người dùng chọn | F15: Đúng | G15: P0 | H15: Chưa chạy
A16: TC12 | B16: Dữ liệu | C16: Ngày mơ hồ phải hỏi lại | D16: Cột toàn giá trị như 03/04/2026 | E16: V05 xuất hiện | F16: Đúng | G16: P1 | H16: Chưa chạy
A17: TC13 | B17: Dữ liệu | C17: Số kiểu VN 1.234.567,89 đọc đúng | D17: Cột số kiểu VN | E17: Giá trị 1234567.89 | F17: 1234567.89 | G17: P1 | H17: Chưa chạy
A18: TC14 | B18: Dữ liệu | C18: Hai cột Ghi nợ/Ghi có thành amount có dấu | D18: debit=100, credit trống; credit=50, debit trống | E18: −100 và +50 | F18: -100 / 50 | G18: P0 | H18: Chưa chạy
A19: TC15 | B19: Dữ liệu | C19: Thanh toán một phần dùng open_amount | D19: amount=100, open_amount=40 | E19: Event chỉ 40 | F19: 40 | G19: P0 | H19: Chưa chạy
A20: TC16 | B20: Dữ liệu | C20: Khoản quá hạn xếp vào tuần 1 và gắn nhãn | D20: due_date < as_of, còn mở | E20: Có trong tuần 1; V14 | F20: Đúng | G20: P1 | H20: Chưa chạy
A21: TC17 | B21: Dữ liệu | C21: Khoản ngoài 13 tuần không tính | D21: due_date sau tuần 13 | E21: Không vào forecast; V15 | F21: Đúng | G21: P1 | H21: Chưa chạy
A22: TC18 | B22: Dữ liệu | C22: Dòng thiếu ngày bị loại và báo | D22: Một dòng date rỗng | E22: Loại dòng; V04 nêu số dòng | F22: Đúng | G22: P0 | H22: Chưa chạy
A23: TC19 | B23: Dữ liệu | C23: Số dư trong file lệch số dư tính lại | D23: File thiếu một dòng | E23: V18 nêu mức lệch | F23: Đúng | G23: P1 | H23: Chưa chạy
A24: TC20 | B24: Preset sàn | C24: Net payout lệch công thức thì cảnh báo | D24: gross=45.000.000, phí=5.400.000, hold=4.500.000, ship=0, net=31.500.000 | E24: V21 nêu lệch 3.600.000 | F24: 3600000 | G24: P1 | H24: Chưa chạy
... A30: TC26 | B30: Hiệu năng | C30: File vượt giới hạn bị chặn | D30: File lớn hơn P10 | E30: V22 | F30: Đúng | G30: P1 | H30: Chưa chạy

Sheet Phi chức năng
A1: Yêu cầu phi chức năng và bảo mật
A2: Con số là đề xuất; dev xác nhận theo hạ tầng thực tế rồi điền cột vàng.
A4: ID | B4: Nhóm | C4: Yêu cầu | D4: Đề xuất | E4: Ghi chú | F4: Dev xác nhận
A5: NF01 | B5: Hiệu năng | C5: Số dòng tối đa mỗi file | D5: 50.000 dòng (đề xuất) | E5: Quá giới hạn thì V22
A6: NF02 | B6: Hiệu năng | C6: Thời gian chạy forecast 13 tuần cho 3 đồng tiền | D6: Dưới vài giây với dữ liệu demo (đề xuất) | E6: Dev đo và điền
A7: NF03 | B7: Bảo mật | C7: Dữ liệu gửi cho LLM bên ngoài | D7: Chỉ gửi số đã tổng hợp và alias; không gửi số tài khoản, tên thật | E7: Khớp G05
A8: NF04 | B8: Bảo mật | C8: Xóa dữ liệu | D8: Người dùng xóa được file đã tải và các run liên quan | E8: -
A9: NF05 | B9: Bảo mật | C9: Dữ liệu demo | D9: Dữ liệu giả lập, ghi rõ trên giao diện | E9: Banner 'Dữ liệu mô phỏng' đã có
A10: NF06 | B10: Bảo mật | C10: Khóa API | D10: Không lưu trong code hoặc cùng dữ liệu người dùng | E10: -
A11: NF07 | B11: Truy vết | C11: Audit | D11: Mỗi run lưu data_hash, formula_version, giả định; mỗi approval lưu thời điểm và người duyệt | E11: Xem Mô hình dữ liệu
A12: NF08 | B12: Độ tin cậy | C12: Tính xác định | D12: Cùng input và cùng phiên bản công thức thì cùng output | E12: N7
A13: NF09 | B13: Ngôn ngữ | C13: Giao diện | D13: Chốt ở D10 (Việt hay Anh); báo cáo thi nộp có thể cần tiếng Anh | E13: -
A14: NF10 | B14: Khả dụng | C14: Hoạt động khi AI ngoài lỗi | D14: Phần dashboard và forecast vẫn chạy; chỉ khung hỏi AI báo lỗi | E14: Demo không phụ thuộc mạng
A15: NF11 | B15: Truy cập | C15: Thiết bị | D15: Dùng tốt trên laptop; mobile xem được dashboard | E15: Xem lại khi có thời gian

Sheet Quyết định mở
A1: ID | B1: Quyết định | C1: Lựa chọn | D1: Đề xuất | E1: Nếu chọn sai | F1: Người chốt | G1: Hạn | H1: Quyết định cuối | I1: Trạng thái
A2: D01 | B2: Phạm vi câu 'nên để tiền vào đâu' | C2: A. Chỉ nêu phần dư an toàn và các cách dùng (trả nợ sớm, nhập hàng, dự phòng) kèm đánh đổi. B. Gợi ý sản phẩm tài chính cụ thể | D2: A | E2: B kéo theo pháp lý và độ chính xác; không làm kịp MVP | I2: Chưa chốt
A3: D02 | B3: Số đồng tiền trong MVP | C3: A. VND trước, CNY/USD cơ bản. B. Cả ba đồng tiền sâu như nhau | D3: A (xác nhận bằng phỏng vấn seller) | E3: Làm cả ba sâu dễ trễ hạn | I3: Chưa chốt
A4: D03 | B4: 'AI' gồm những gì | C4: A. Engine tính + LLM giải thích. B. Thêm mô hình ML/thống kê dự báo thu | D4: A cho P0, thống kê đơn giản (F21) cho P1 | E4: Nói 'AI dự báo' khi không có ML sẽ bị hỏi vặn | I4: Chưa chốt
A5: D04 | B5: Quy ước tuần | C5: A. Tuần 1 bắt đầu đúng ngày chốt. B. Tuần theo lịch (thứ Hai–Chủ nhật) | D5: A | E5: Ảnh hưởng tuần của từng event | I5: Chưa chốt
A6: D05 | B6: Khoản quá hạn xếp vào đâu | C6: A. Tuần 1 và gắn nhãn. B. Loại và báo. C. Cho người dùng chọn | D6: A | E6: Ảnh hưởng độ đúng của tuần 1 | I6: Chưa chốt
A7: D06 | B7: Ngưỡng an toàn mặc định | C7: A. 4 tuần chi ra trung bình. B. Người dùng tự nhập, không gợi ý | D7: A, cho sửa | E7: Ngưỡng quyết định cảnh báo | I7: Chưa chốt
A8: D07 | B8: Dữ liệu demo | C8: A. Giả lập hoàn toàn. B. Có thêm file thật đã ẩn danh của seller | D8: B nếu xin được; A là mức tối thiểu | E8: Dữ liệu thật tăng độ tin cậy | I8: Chưa chốt
A9: D08 | B9: LLM dùng loại nào và dữ liệu gửi đi | C9: Chọn nhà cung cấp, quyết định có gửi dữ liệu người dùng ra ngoài không | D9: Gửi số tổng hợp, không gửi dữ liệu thô (G05) | E9: Rủi ro bảo mật và điều khoản cuộc thi | I9: Chưa chốt
A10: D09 | B10: Persona và ngôn ngữ UI | C10: A. Chủ shop/kế toán (tiếng đơn giản). B. CFO (thuật ngữ) | D10: A | E10: Hiện UI đang nghiêng về B | I10: Chưa chốt
A11: D10 | B11: Ngôn ngữ giao diện | C11: A. Việt. B. Anh. C. Có chuyển đổi | D11: C nếu kịp; bản nộp quốc tế cần tiếng Anh | E11: Ảnh hưởng toàn bộ copy | I11: Chưa chốt
A12: D11 | B12: Báo cáo PDF hay chỉ web | C12: A. Có PDF. B. Chỉ web | D12: A cho P1 | E12: Báo cáo là đầu ra chính cho SME | I12: Chưa chốt
A13: D12 | B13: Độ trễ thu tiền mặc định | C13: Giá trị cho P06 | D13: 0 ngày, người dùng chỉnh | E13: Ảnh hưởng ngày vào của phải thu | I13: Chưa chốt
A14: D13 | B14: Có cần nhập tay thay cho upload không | C14: Form nhập số dư và vài khoản cho shop không có file | D14: Có form tối thiểu cho số dư, ngưỡng, khoản phải trả | E14: Hạ rào cản dùng thử | I14: Chưa chốt

Sheet Lộ trình
A1: Lộ trình đề xuất 12/10 đến 20/10
A2: Đề xuất để team chỉnh. Hạn nộp chính thức lấy theo thể lệ cuộc thi; nên nộp sớm hơn hạn.
A4: Ngày | B4: Mục tiêu | C4: Việc cho Business | D4: Việc cho Dev | E4: Xong khi | F4: Trạng thái
A5: 46307 | B5: Chốt phạm vi | C5: Chốt các quyết định D01-D06; gửi workbook này cho dev | D5: Đọc spec, hỏi lại chỗ chưa rõ | E5: Quyết định D01-D06 đã chốt | F5: Chưa làm
A6: 46308 | B6: Dữ liệu demo | C6: Dựng bộ dữ liệu demo + file mẫu; điền tab Test case | D6: Dựng engine lõi: cash_event + forecast VND | E6: TC01-TC06 chạy được | F6: Chưa làm
A7: 46309 | B7: Engine + cảnh báo | C7: Phỏng vấn 2-3 seller, xin file mẫu | D7: Cảnh báo 2 mức + drivers | E7: TC02-TC04, TC25 đạt | F7: Chưa làm
A8: 46310 | B8: Upload và ánh xạ | C8: Chuẩn bị file thật để thử ánh xạ | D8: Upload, ánh xạ cột, kiểm tra dữ liệu | E8: V01-V10 có test | F8: Chưa làm
A9: 46311 | B9: Kịch bản | C9: Kiểm tra số kịch bản bằng tay | D9: Kịch bản dời trả (P0) + so sánh | E9: TC07, TC08 đạt | F9: Chưa làm
A10: 46312 | B10: AI | C10: Viết bộ câu hỏi nghiệm thu | D10: AI gọi tool + guardrail | E10: TC22-TC24 đạt | F10: Chưa làm
A11: 46313 | B11: Giao diện | C11: Rà thuật ngữ UI | D11: Sửa UI theo sheet Đầu ra và Thuật ngữ | E11: Màn hình M01-M08 chạy | F11: Chưa làm
A12: 46314 | B12: Chạy thử toàn bộ | C12: Chạy end-to-end bằng bộ demo; quay video | D12: Sửa lỗi; đóng băng tính năng | E12: Toàn bộ test P0 đạt | F12: Chưa làm
A13: 46315 | B13: Nộp bài | C13: Nộp trước hạn, kiểm tra giờ chính thức trong thể lệ | D13: Hỗ trợ lỗi phút chót | E13: Đã nộp | F13: Chưa làm

Sheet Preset sàn
A1: Phụ lục: preset đọc báo cáo đối soát Shopee / TikTok Shop
A2: Preset chỉ là bộ ánh xạ + quy tắc dựng sẵn cho file của sàn. Lõi sản phẩm vẫn hoạt động với file bất kỳ.
A4: Mục | B4: Nội dung
A5: Mục đích | B5: Giúp shop bán trên sàn không phải ánh xạ cột thủ công, và cho dữ liệu demo sát thực tế.
A6: Đầu vào | B6: Báo cáo đối soát/thanh toán xuất từ Seller Centre (tên báo cáo và cột phải xác minh từ file thật).
A7: Đầu ra | B7: Mỗi dòng settlement → event payout vào expected_payout_date với số tiền = net_payout; nếu có hold → thêm event hold_release (+hold) vào ngày giải phóng.
A8: Kiểm tra | B8: gross − platform_fee − refunds − shipping_or_COD_fee − hold so với net_payout; lệch quá P04 thì V21.
A9: Không làm | B9: Không viết cứng chính sách của sàn vào lõi; mọi mức phí/ngày là cấu hình của preset.
A10: Nguồn xác minh | B10: Workbook 'FlowWise_Shopee_TikTok_nghiep_vu.xlsx': tab Quy tắc nghiệp vụ và Cấu trúc settlement.
A12: Bảng ánh xạ cột (điền khi có file thật)
A13: Cột schema | B13: Tên cột thật - Shopee | C13: Tên cột thật - TikTok Shop | D13: Đã xác minh
A14: gross_sales | D14: Chưa
A15: platform_fee | D15: Chưa
A16: refunds | D16: Chưa
A17: shipping_or_COD_fee | D17: Chưa
A18: reserve_or_hold | D18: Chưa
A19: net_payout | D19: Chưa
A20: expected_payout_date | D20: Chưa
A21: actual_payout_date | D21: Chưa

Sheet Thuật ngữ & UI copy
A1: Thuật ngữ và cách viết trên giao diện
A4: Thuật ngữ nội bộ / UI hiện tại | B4: Nghĩa | C4: Nên hiển thị cho người dùng
A5: cash_event | B5: Một khoản tiền vào/ra có ngày, số tiền, đồng tiền | C5: Khoản tiền
A6: as_of_date | B6: Ngày chốt số liệu; điểm bắt đầu Tuần 1 | C6: Ngày chốt số liệu
A7: opening / closing | B7: Số dư đầu / cuối tuần | C7: Số dư đầu tuần / cuối tuần
A8: buffer | B8: Ngưỡng tiền an toàn tối thiểu | C8: Mức tiền an toàn
A9: BELOW_BUFFER | B9: Số dư thấp hơn ngưỡng nhưng chưa âm | C9: Dưới mức an toàn
A10: SHORTFALL | B10: Số dư âm | C10: Thiếu tiền
A11: baseline | B11: Dự báo khi không làm gì | C11: Hiện trạng
A12: scenario | B12: Phương án thử nghiệm | C12: Phương án thử
A13: settlement / payout | B13: Kỳ đối soát và tiền sàn trả về | C13: Tiền sàn trả về
A14: reserve_or_hold / escrow | B14: Tiền sàn giữ lại tạm thời | C14: Tiền sàn đang giữ
A15: receivable / payable | B15: Khoản phải thu / phải trả | C15: Tiền khách nợ / Tiền phải trả
... A19: Deterministic Engine | B19: (thuật ngữ trên UI hiện tại) | C19: Cách tính cố định, có thể kiểm tra lại
